[2021-03-04 14:25:56] ERROR    Exception on /uploadajax [POST]
Traceback (most recent call last):
  File "C:\Users\reyme\AppData\Local\Programs\Python\Python39\lib\site-packages\flask\app.py", line 2447, in wsgi_app
    response = self.full_dispatch_request()
  File "C:\Users\reyme\AppData\Local\Programs\Python\Python39\lib\site-packages\flask\app.py", line 1952, in full_dispatch_request
    rv = self.handle_user_exception(e)
  File "C:\Users\reyme\AppData\Local\Programs\Python\Python39\lib\site-packages\flask\app.py", line 1821, in handle_user_exception
    reraise(exc_type, exc_value, tb)
  File "C:\Users\reyme\AppData\Local\Programs\Python\Python39\lib\site-packages\flask\_compat.py", line 39, in reraise
    raise value
  File "C:\Users\reyme\AppData\Local\Programs\Python\Python39\lib\site-packages\flask\app.py", line 1950, in full_dispatch_request
    rv = self.dispatch_request()
  File "C:\Users\reyme\AppData\Local\Programs\Python\Python39\lib\site-packages\flask\app.py", line 1936, in dispatch_request
    return self.view_functions[rule.endpoint](**req.view_args)
  File "C:\Users\reyme\OneDrive\Documents\Coding\RevalEquip\__init__.py", line 63, in upldfile
    files.save(os.path.join(updir, filename))
  File "C:\Users\reyme\AppData\Local\Programs\Python\Python39\lib\site-packages\werkzeug\datastructures.py", line 3066, in save
    dst = open(dst, "wb")
FileNotFoundError: [Errno 2] No such file or directory: 'C:\\Users\\reyme\\OneDrive\\Documents\\Coding\\RevalEquip\\upload/achtergrond.jpg'
[2021-03-04 14:26:24] ERROR    Exception on /uploadajax [POST]
Traceback (most recent call last):
  File "C:\Users\reyme\AppData\Local\Programs\Python\Python39\lib\site-packages\flask\app.py", line 2447, in wsgi_app
    response = self.full_dispatch_request()
  File "C:\Users\reyme\AppData\Local\Programs\Python\Python39\lib\site-packages\flask\app.py", line 1952, in full_dispatch_request
    rv = self.handle_user_exception(e)
  File "C:\Users\reyme\AppData\Local\Programs\Python\Python39\lib\site-packages\flask\app.py", line 1821, in handle_user_exception
    reraise(exc_type, exc_value, tb)
  File "C:\Users\reyme\AppData\Local\Programs\Python\Python39\lib\site-packages\flask\_compat.py", line 39, in reraise
    raise value
  File "C:\Users\reyme\AppData\Local\Programs\Python\Python39\lib\site-packages\flask\app.py", line 1950, in full_dispatch_request
    rv = self.dispatch_request()
  File "C:\Users\reyme\AppData\Local\Programs\Python\Python39\lib\site-packages\flask\app.py", line 1936, in dispatch_request
    return self.view_functions[rule.endpoint](**req.view_args)
  File "C:\Users\reyme\OneDrive\Documents\Coding\RevalEquip\__init__.py", line 63, in upldfile
    files.save(os.path.join(updir, filename))
  File "C:\Users\reyme\AppData\Local\Programs\Python\Python39\lib\site-packages\werkzeug\datastructures.py", line 3066, in save
    dst = open(dst, "wb")
FileNotFoundError: [Errno 2] No such file or directory: 'C:\\Users\\reyme\\OneDrive\\Documents\\Coding\\RevalEquip\\upload/achtergrond.jpg'
[2021-03-04 14:29:11] ERROR    Exception on /uploadajax [POST]
Traceback (most recent call last):
  File "C:\Users\reyme\AppData\Local\Programs\Python\Python39\lib\site-packages\flask\app.py", line 2447, in wsgi_app
    response = self.full_dispatch_request()
  File "C:\Users\reyme\AppData\Local\Programs\Python\Python39\lib\site-packages\flask\app.py", line 1952, in full_dispatch_request
    rv = self.handle_user_exception(e)
  File "C:\Users\reyme\AppData\Local\Programs\Python\Python39\lib\site-packages\flask\app.py", line 1821, in handle_user_exception
    reraise(exc_type, exc_value, tb)
  File "C:\Users\reyme\AppData\Local\Programs\Python\Python39\lib\site-packages\flask\_compat.py", line 39, in reraise
    raise value
  File "C:\Users\reyme\AppData\Local\Programs\Python\Python39\lib\site-packages\flask\app.py", line 1950, in full_dispatch_request
    rv = self.dispatch_request()
  File "C:\Users\reyme\AppData\Local\Programs\Python\Python39\lib\site-packages\flask\app.py", line 1936, in dispatch_request
    return self.view_functions[rule.endpoint](**req.view_args)
  File "C:\Users\reyme\OneDrive\Documents\Coding\RevalEquip\__init__.py", line 63, in upldfile
    files.save(os.path.join(updir, filename))
  File "C:\Users\reyme\AppData\Local\Programs\Python\Python39\lib\site-packages\werkzeug\datastructures.py", line 3066, in save
    dst = open(dst, "wb")
FileNotFoundError: [Errno 2] No such file or directory: 'C:\\Users\\reyme\\OneDrive\\Documents\\Coding\\RevalEquip\\upload/achtergrond.jpg'
[2021-03-04 14:30:49] ERROR    Exception on /uploadajax [POST]
Traceback (most recent call last):
  File "C:\Users\reyme\AppData\Local\Programs\Python\Python39\lib\site-packages\flask\app.py", line 2447, in wsgi_app
    response = self.full_dispatch_request()
  File "C:\Users\reyme\AppData\Local\Programs\Python\Python39\lib\site-packages\flask\app.py", line 1952, in full_dispatch_request
    rv = self.handle_user_exception(e)
  File "C:\Users\reyme\AppData\Local\Programs\Python\Python39\lib\site-packages\flask\app.py", line 1821, in handle_user_exception
    reraise(exc_type, exc_value, tb)
  File "C:\Users\reyme\AppData\Local\Programs\Python\Python39\lib\site-packages\flask\_compat.py", line 39, in reraise
    raise value
  File "C:\Users\reyme\AppData\Local\Programs\Python\Python39\lib\site-packages\flask\app.py", line 1950, in full_dispatch_request
    rv = self.dispatch_request()
  File "C:\Users\reyme\AppData\Local\Programs\Python\Python39\lib\site-packages\flask\app.py", line 1936, in dispatch_request
    return self.view_functions[rule.endpoint](**req.view_args)
  File "C:\Users\reyme\OneDrive\Documents\Coding\RevalEquip\__init__.py", line 63, in upldfile
    files.save(os.path.join(updir, filename))
  File "C:\Users\reyme\AppData\Local\Programs\Python\Python39\lib\site-packages\werkzeug\datastructures.py", line 3066, in save
    dst = open(dst, "wb")
FileNotFoundError: [Errno 2] No such file or directory: 'C:\\Users\\reyme\\OneDrive\\Documents\\Coding\\RevalEquip\\upload/achtergrond.jpg'
[2021-03-04 14:33:25] ERROR    Exception on /uploadajax [POST]
Traceback (most recent call last):
  File "C:\Users\reyme\AppData\Local\Programs\Python\Python39\lib\site-packages\flask\app.py", line 2447, in wsgi_app
    response = self.full_dispatch_request()
  File "C:\Users\reyme\AppData\Local\Programs\Python\Python39\lib\site-packages\flask\app.py", line 1952, in full_dispatch_request
    rv = self.handle_user_exception(e)
  File "C:\Users\reyme\AppData\Local\Programs\Python\Python39\lib\site-packages\flask\app.py", line 1821, in handle_user_exception
    reraise(exc_type, exc_value, tb)
  File "C:\Users\reyme\AppData\Local\Programs\Python\Python39\lib\site-packages\flask\_compat.py", line 39, in reraise
    raise value
  File "C:\Users\reyme\AppData\Local\Programs\Python\Python39\lib\site-packages\flask\app.py", line 1950, in full_dispatch_request
    rv = self.dispatch_request()
  File "C:\Users\reyme\AppData\Local\Programs\Python\Python39\lib\site-packages\flask\app.py", line 1936, in dispatch_request
    return self.view_functions[rule.endpoint](**req.view_args)
  File "C:\Users\reyme\OneDrive\Documents\Coding\RevalEquip\__init__.py", line 63, in upldfile
    files.save(os.path.join(updir, filename))
  File "C:\Users\reyme\AppData\Local\Programs\Python\Python39\lib\site-packages\werkzeug\datastructures.py", line 3066, in save
    dst = open(dst, "wb")
FileNotFoundError: [Errno 2] No such file or directory: 'C:\\Users\\reyme\\OneDrive\\Documents\\Coding\\RevalEquip\\upload/achtergrond.jpg'
[2021-03-04 14:34:14] ERROR    Exception on /uploadajax [POST]
Traceback (most recent call last):
  File "C:\Users\reyme\AppData\Local\Programs\Python\Python39\lib\site-packages\flask\app.py", line 2447, in wsgi_app
    response = self.full_dispatch_request()
  File "C:\Users\reyme\AppData\Local\Programs\Python\Python39\lib\site-packages\flask\app.py", line 1952, in full_dispatch_request
    rv = self.handle_user_exception(e)
  File "C:\Users\reyme\AppData\Local\Programs\Python\Python39\lib\site-packages\flask\app.py", line 1821, in handle_user_exception
    reraise(exc_type, exc_value, tb)
  File "C:\Users\reyme\AppData\Local\Programs\Python\Python39\lib\site-packages\flask\_compat.py", line 39, in reraise
    raise value
  File "C:\Users\reyme\AppData\Local\Programs\Python\Python39\lib\site-packages\flask\app.py", line 1950, in full_dispatch_request
    rv = self.dispatch_request()
  File "C:\Users\reyme\AppData\Local\Programs\Python\Python39\lib\site-packages\flask\app.py", line 1936, in dispatch_request
    return self.view_functions[rule.endpoint](**req.view_args)
  File "C:\Users\reyme\OneDrive\Documents\Coding\RevalEquip\__init__.py", line 63, in upldfile
    files.save(os.path.join(updir, filename))
  File "C:\Users\reyme\AppData\Local\Programs\Python\Python39\lib\site-packages\werkzeug\datastructures.py", line 3066, in save
    dst = open(dst, "wb")
FileNotFoundError: [Errno 2] No such file or directory: 'C:\\Users\\reyme\\OneDrive\\Documents\\Coding\\RevalEquip\\upload/achtergrond.jpg'
[2021-03-04 14:35:17] ERROR    Exception on /uploadajax [POST]
Traceback (most recent call last):
  File "C:\Users\reyme\AppData\Local\Programs\Python\Python39\lib\site-packages\flask\app.py", line 2447, in wsgi_app
    response = self.full_dispatch_request()
  File "C:\Users\reyme\AppData\Local\Programs\Python\Python39\lib\site-packages\flask\app.py", line 1952, in full_dispatch_request
    rv = self.handle_user_exception(e)
  File "C:\Users\reyme\AppData\Local\Programs\Python\Python39\lib\site-packages\flask\app.py", line 1821, in handle_user_exception
    reraise(exc_type, exc_value, tb)
  File "C:\Users\reyme\AppData\Local\Programs\Python\Python39\lib\site-packages\flask\_compat.py", line 39, in reraise
    raise value
  File "C:\Users\reyme\AppData\Local\Programs\Python\Python39\lib\site-packages\flask\app.py", line 1950, in full_dispatch_request
    rv = self.dispatch_request()
  File "C:\Users\reyme\AppData\Local\Programs\Python\Python39\lib\site-packages\flask\app.py", line 1936, in dispatch_request
    return self.view_functions[rule.endpoint](**req.view_args)
  File "C:\Users\reyme\OneDrive\Documents\Coding\RevalEquip\__init__.py", line 63, in upldfile
    files.save(os.path.join(updir, filename))
  File "C:\Users\reyme\AppData\Local\Programs\Python\Python39\lib\site-packages\werkzeug\datastructures.py", line 3066, in save
    dst = open(dst, "wb")
FileNotFoundError: [Errno 2] No such file or directory: 'C:\\Users\\reyme\\OneDrive\\Documents\\Coding\\RevalEquip\\upload/achtergrond.jpg'
[2021-03-04 14:36:38] ERROR    Exception on /uploadajax [POST]
Traceback (most recent call last):
  File "C:\Users\reyme\AppData\Local\Programs\Python\Python39\lib\site-packages\flask\app.py", line 2447, in wsgi_app
    response = self.full_dispatch_request()
  File "C:\Users\reyme\AppData\Local\Programs\Python\Python39\lib\site-packages\flask\app.py", line 1953, in full_dispatch_request
    return self.finalize_request(rv)
  File "C:\Users\reyme\AppData\Local\Programs\Python\Python39\lib\site-packages\flask\app.py", line 1968, in finalize_request
    response = self.make_response(rv)
  File "C:\Users\reyme\AppData\Local\Programs\Python\Python39\lib\site-packages\flask\app.py", line 2097, in make_response
    raise TypeError(
TypeError: The view function did not return a valid response. The function either returned None or ended without a return statement.
[2021-03-04 14:36:52] ERROR    Exception on /uploadajax [POST]
Traceback (most recent call last):
  File "C:\Users\reyme\AppData\Local\Programs\Python\Python39\lib\site-packages\flask\app.py", line 2447, in wsgi_app
    response = self.full_dispatch_request()
  File "C:\Users\reyme\AppData\Local\Programs\Python\Python39\lib\site-packages\flask\app.py", line 1952, in full_dispatch_request
    rv = self.handle_user_exception(e)
  File "C:\Users\reyme\AppData\Local\Programs\Python\Python39\lib\site-packages\flask\app.py", line 1821, in handle_user_exception
    reraise(exc_type, exc_value, tb)
  File "C:\Users\reyme\AppData\Local\Programs\Python\Python39\lib\site-packages\flask\_compat.py", line 39, in reraise
    raise value
  File "C:\Users\reyme\AppData\Local\Programs\Python\Python39\lib\site-packages\flask\app.py", line 1950, in full_dispatch_request
    rv = self.dispatch_request()
  File "C:\Users\reyme\AppData\Local\Programs\Python\Python39\lib\site-packages\flask\app.py", line 1936, in dispatch_request
    return self.view_functions[rule.endpoint](**req.view_args)
  File "C:/Users/reyme/OneDrive/Documents/Coding/RevalEquip/__init__.py", line 63, in upldfile
    files.save(os.path.join(updir, filename))
  File "C:\Users\reyme\AppData\Local\Programs\Python\Python39\lib\site-packages\werkzeug\datastructures.py", line 3066, in save
    dst = open(dst, "wb")
FileNotFoundError: [Errno 2] No such file or directory: 'C:\\Users\\reyme\\OneDrive\\Documents\\Coding\\RevalEquip\\static\\images\\upload\\achtergrond.jpg'
[2021-03-04 14:37:06] ERROR    Exception on /uploadajax [POST]
Traceback (most recent call last):
  File "C:\Users\reyme\AppData\Local\Programs\Python\Python39\lib\site-packages\flask\app.py", line 2447, in wsgi_app
    response = self.full_dispatch_request()
  File "C:\Users\reyme\AppData\Local\Programs\Python\Python39\lib\site-packages\flask\app.py", line 1952, in full_dispatch_request
    rv = self.handle_user_exception(e)
  File "C:\Users\reyme\AppData\Local\Programs\Python\Python39\lib\site-packages\flask\app.py", line 1821, in handle_user_exception
    reraise(exc_type, exc_value, tb)
  File "C:\Users\reyme\AppData\Local\Programs\Python\Python39\lib\site-packages\flask\_compat.py", line 39, in reraise
    raise value
  File "C:\Users\reyme\AppData\Local\Programs\Python\Python39\lib\site-packages\flask\app.py", line 1950, in full_dispatch_request
    rv = self.dispatch_request()
  File "C:\Users\reyme\AppData\Local\Programs\Python\Python39\lib\site-packages\flask\app.py", line 1936, in dispatch_request
    return self.view_functions[rule.endpoint](**req.view_args)
  File "C:/Users/reyme/OneDrive/Documents/Coding/RevalEquip/__init__.py", line 63, in upldfile
    files.save(os.path.join(updir, filename))
  File "C:\Users\reyme\AppData\Local\Programs\Python\Python39\lib\site-packages\werkzeug\datastructures.py", line 3066, in save
    dst = open(dst, "wb")
FileNotFoundError: [Errno 2] No such file or directory: 'C:\\Users\\reyme\\OneDrive\\Documents\\Coding\\RevalEquip\\static\\images\\upload\\achtergrond.jpg'
[2021-03-04 14:37:59] ERROR    Exception on /uploadajax [POST]
Traceback (most recent call last):
  File "C:\Users\reyme\AppData\Local\Programs\Python\Python39\lib\site-packages\flask\app.py", line 2447, in wsgi_app
    response = self.full_dispatch_request()
  File "C:\Users\reyme\AppData\Local\Programs\Python\Python39\lib\site-packages\flask\app.py", line 1952, in full_dispatch_request
    rv = self.handle_user_exception(e)
  File "C:\Users\reyme\AppData\Local\Programs\Python\Python39\lib\site-packages\flask\app.py", line 1821, in handle_user_exception
    reraise(exc_type, exc_value, tb)
  File "C:\Users\reyme\AppData\Local\Programs\Python\Python39\lib\site-packages\flask\_compat.py", line 39, in reraise
    raise value
  File "C:\Users\reyme\AppData\Local\Programs\Python\Python39\lib\site-packages\flask\app.py", line 1950, in full_dispatch_request
    rv = self.dispatch_request()
  File "C:\Users\reyme\AppData\Local\Programs\Python\Python39\lib\site-packages\flask\app.py", line 1936, in dispatch_request
    return self.view_functions[rule.endpoint](**req.view_args)
  File "C:\Users\reyme\OneDrive\Documents\Coding\RevalEquip\__init__.py", line 63, in upldfile
    files.save(os.path.join(updir, filename))
  File "C:\Users\reyme\AppData\Local\Programs\Python\Python39\lib\site-packages\werkzeug\datastructures.py", line 3066, in save
    dst = open(dst, "wb")
FileNotFoundError: [Errno 2] No such file or directory: 'C:\\Users\\reyme\\OneDrive\\Documents\\Coding\\RevalEquip\\static\\images\\upload\\achtergrond.jpg'
[2021-03-04 15:08:34] ERROR    Exception on /newEquipmentPicture [GET]
Traceback (most recent call last):
  File "C:\Users\reyme\AppData\Local\Programs\Python\Python39\lib\site-packages\flask\app.py", line 2447, in wsgi_app
    response = self.full_dispatch_request()
  File "C:\Users\reyme\AppData\Local\Programs\Python\Python39\lib\site-packages\flask\app.py", line 1952, in full_dispatch_request
    rv = self.handle_user_exception(e)
  File "C:\Users\reyme\AppData\Local\Programs\Python\Python39\lib\site-packages\flask\app.py", line 1821, in handle_user_exception
    reraise(exc_type, exc_value, tb)
  File "C:\Users\reyme\AppData\Local\Programs\Python\Python39\lib\site-packages\flask\_compat.py", line 39, in reraise
    raise value
  File "C:\Users\reyme\AppData\Local\Programs\Python\Python39\lib\site-packages\flask\app.py", line 1950, in full_dispatch_request
    rv = self.dispatch_request()
  File "C:\Users\reyme\AppData\Local\Programs\Python\Python39\lib\site-packages\flask\app.py", line 1936, in dispatch_request
    return self.view_functions[rule.endpoint](**req.view_args)
  File "C:\Users\reyme\OneDrive\Documents\Coding\RevalEquip\blue_equipment.py", line 329, in new_equipment_picture
    c.execute(sql_string)
sqlite3.OperationalError: database is locked
[2021-03-04 15:12:43] ERROR    Exception on /newEquipmentPicture [GET]
Traceback (most recent call last):
  File "C:\Users\reyme\AppData\Local\Programs\Python\Python39\lib\site-packages\flask\app.py", line 2447, in wsgi_app
    response = self.full_dispatch_request()
  File "C:\Users\reyme\AppData\Local\Programs\Python\Python39\lib\site-packages\flask\app.py", line 1952, in full_dispatch_request
    rv = self.handle_user_exception(e)
  File "C:\Users\reyme\AppData\Local\Programs\Python\Python39\lib\site-packages\flask\app.py", line 1821, in handle_user_exception
    reraise(exc_type, exc_value, tb)
  File "C:\Users\reyme\AppData\Local\Programs\Python\Python39\lib\site-packages\flask\_compat.py", line 39, in reraise
    raise value
  File "C:\Users\reyme\AppData\Local\Programs\Python\Python39\lib\site-packages\flask\app.py", line 1950, in full_dispatch_request
    rv = self.dispatch_request()
  File "C:\Users\reyme\AppData\Local\Programs\Python\Python39\lib\site-packages\flask\app.py", line 1936, in dispatch_request
    return self.view_functions[rule.endpoint](**req.view_args)
  File "C:\Users\reyme\OneDrive\Documents\Coding\RevalEquip\blue_equipment.py", line 329, in new_equipment_picture
    c.execute(sql_string)
sqlite3.OperationalError: database is locked
